Workbook

Sheet Leia-me
A1: Base de dados – Valor Adicionado e fatores socioeconômicos dos municípios do RN
A2: Extração: 09/10/2026, direto das APIs oficiais (IBGE/SIDRA, IBGE Cidades, IpeaData, Observatório Sebrae). 167 municípios + total do RN.
A4: ABAS
A5: Municipios_RN – 1 linha por município. Colunas agrupadas por setor (Indústria, Serviços, Administração), mais perfil empresarial, socioeconômico e controles. Rankings e % são fórmulas.
A6: Ranking_Setores – Top 15 por setor, por participação no VAB municipal e por VAB absoluto (fórmulas).
A7: Correlacoes – Correlação entre peso de cada setor no VAB e indicadores sociais/empresariais (fórmulas CORREL).
A8: Serie_Historica – Formato longo, filtrável por município e série. PIB e VAB setorial em preços correntes (IBGE, 2002–2023/2021) e em preços constantes de 2010 (IpeaData, 2002–2021), com variação real.
A9: Serie_Participacao – Participação % de cada setor no VAB municipal, ano a ano (2002–2021), pronta para gráfico de linhas.
A10: CNAE_PO_10municipios – Pessoal ocupado por seção CNAE (só 10 municípios cobertos pelo IBGE).
A12: FONTES
A13: IBGE/SIDRA tab. 5938 – PIB dos Municípios (ref. 2010): https://sidra.ibge.gov.br/tabela/5938
A14: IBGE/SIDRA tab. 6579 – Estimativas de população (2021): https://sidra.ibge.gov.br/tabela/6579
... A35: Texto azul = dado importado da fonte · preto = fórmula · verde = fórmula que puxa de outra aba · célula vazia = inexistente/sigiloso/não disponível. Valores monetários do PIB/VAB em mil R$.

Sheet Municipios_RN
A1: IDENTIFICAÇÃO | C1: ECONOMIA GERAL | K1: INDÚSTRIA | S1: SERVIÇOS (exceto adm. pública) | AA1: ADMINISTRAÇÃO PÚBLICA | AI1: AGROPECUÁRIA (ref.) | AK1: PERFIL EMPRESARIAL | AZ1: SOCIOECONÔMICO | BL1: CONTROLE DE QUALIDADE
A2: Código IBGE | B2: Município | C2: PIB 2021 (mil R$) | D2: PIB 2022 (mil R$) | E2: PIB 2023 (mil R$) | F2: VAB total 2021 (mil R$) | G2: Impostos líq. 2021 (mil R$) | H2: População estimada 2021 | I2: PIB per capita 2021 (R$) – IBGE | J2: PIB per capita 2023 (R$) – IBGE | K2: VAB Indústria 2021 (mil R$) | L2: Part. Indústria no VAB (%) | M2: VAB Indústria per capita (R$) | N2: Ranking RN – part. % | O2: Ranking RN – VAB absoluto | P2: Estab. ativos Indústria (Sebrae) | Q2: % estab. Indústria no total | R2: Estab. Indústria EPP + demais portes | S2: VAB Serviços 2021 (mil R$) | T2: Part. Serviços no VAB (%) | U2: VAB Serviços per capita (R$) | V2: Ranking RN – part. % | W2: Ranking RN – VAB absoluto | X2: Estab. ativos Comércio (Sebrae) | Y2: Estab. ativos Serviços (Sebrae) | Z2: % estab. Comércio+Serviços no total | AA2: VAB Adm. pública 2021 (mil R$) | AB2: Part. Adm. pública no VAB (%) | AC2: VAB Adm. per capita (R$) | AD2: Ranking RN – part. % | AE2: Ranking RN – VAB absoluto | AF2: Receita de transferências (% receita) 2025 | AG2: Receitas orçamentárias brutas 2025 (R$) | AH2: Receita bruta per capita 2025 (R$) | AI2: VAB Agropecuária 2021 (mil R$) | AJ2: Part. Agro no VAB (%) | AK2: Empresas atuantes 2022 (CEMPRE) | AL2: Empresas atuantes 2024 (CEMPRE) | AM2: Unidades locais 2024 (CEMPRE) | AN2: Pessoal ocupado 2024 (CEMPRE) | AO2: Pessoal assalariado 2024 (CEMPRE) | AP2: Salário médio mensal 2024 (SM) | AQ2: Empresas por mil hab. 2024 | AR2: Estab. ativos – total (Sebrae) | AS2: MEI (Sebrae) | AT2: ME (Sebrae) | AU2: EPP (Sebrae) | AV2: Demais portes (Sebrae) | AW2: % MEI nos estab. ativos | AX2: Estab. Agro (Sebrae) | AY2: Estab. Adm. pública (Sebrae) | AZ2: População Censo 2022 | BA2: Área (km²) | BB2: Densidade 2022 (hab/km²) | BC2: IDHM 2010 | BD2: % pop. com renda ≤ ½ SM 2010 | BE2: Escolarização 6–14 anos 2022 (%) | BF2: IDEB anos iniciais 2025 (rede pública) | BG2: IDEB anos finais 2025 (rede pública) | BH2: Esgotamento sanitário adequado 2022 (%) | BI2: Pessoal ocupado formal 2024 | BJ2: Salário médio formal 2024 (SM) | BK2: % da população em emprego formal | BL2: Controle: Σ VAB setores − VAB total | BM2: Controle: VAB + impostos − PIB 2021 | BN2: Controle: PIB pc calculado − IBGE (R$)
A3: 2408102 | B3: Natal | C3: 24186139 | D3: 27497422 | E3: 31162043 | F3: 20775502 | G3: 3410637 | H3: 896708 | I3: 26972.15 | J3: 41477.5 | K3: 2556518 | L3: =IFERROR(K3/F3,"") -> 0.12305445 | M3: =IFERROR(K3*1000/H3,"") -> 2851.0039 | N3: =IF(L3="","",RANK(L3,$L$3:$L$168,0)+COUNTIF($L$3:L3,L3)-1) -> 51 | O3: =IF(K3="","",RANK(K3,$K$3:$K$168,0)+COUNTIF($K$3:K3,K3)-1) -> 1 | P3: 15140 | Q3: =IFERROR(P3/AR3,"") -> 0.1347047 | R3: 2492 | S3: 13347894 | T3: =IFERROR(S3/F3,"") -> 0.64248238 | U3: =IFERROR(S3*1000/H3,"") -> 14885.441 | V3: =IF(T3="","",RANK(T3,$T$3:$T$168,0)+COUNTIF($T$3:T3,T3)-1) -> 1 | W3: =IF(S3="","",RANK(S3,$S$3:$S$168,0)+COUNTIF($S$3:S3,S3)-1) -> 1 | X3: 26454 | Y3: 70281 | Z3: =IFERROR((X3+Y3)/AR3,"") -> 0.86067762 | AA3: 4851091 | AB3: =IFERROR(AA3/F3,"") -> 0.23350054 | AC3: =IFERROR(AA3*1000/H3,"") -> 5409.8893 | AD3: =IF(AB3="","",RANK(AB3,$AB$3:$AB$168,0)+COUNTIF($AB$3:AB3,AB3)-1) -> 150 | AE3: =IF(AA3="","",RANK(AA3,$AA$3:$AA$168,0)+COUNTIF($AA$3:AA3,AA3)-1) -> 1 | AF3: 57.6 | AG3: 4.537308e+09 | AH3: =IFERROR(AG3/AZ3,"") -> 6039.276 | AI3: 19998 | AJ3: =IFERROR(AI3/F3,"") -> 0.00096257602 | AK3: 39666 | AL3: 43817 | AM3: 46732 | AN3: 367921 | AO3: 310411 | AP3: 2.8 | AQ3: =IFERROR(AL3*1000/AZ3,"") -> 58.321576 | AR3: 112394 | AS3: 54887 | AT3: 39467 | AU3: 6729 | AV3: 11311 | AW3: =IFERROR(AS3/AR3,"") -> 0.48834457 | AX3: 278 | AY3: 224 | AZ3: 751300 | BA3: 167.401 | BB3: 4488.03 | BC3: 0.763 | BD3: 35.7 | BE3: 97.86 | BF3: 5 | BG3: 3.9 | BH3: 43.74 | BI3: 367921 | BJ3: 2.8 | BK3: =IFERROR(BI3/AZ3,"") -> 0.4897125 | BL3: =IFERROR(AI3+K3+S3+AA3-F3,"") -> -1 | BM3: =IFERROR(F3+G3-C3,"") -> 0 | BN3: =IF(I3="","",IFERROR(C3*1000/H3-I3,"")) -> -0.0041063535
A4: 2408003 | B4: Mossoró | C4: 8071719 | D4: 9582885 | E4: 10323666 | F4: 6898438 | G4: 1173281 | H4: 303792 | I4: 26569.89 | J4: 39019.51 | K4: 1285190 | L4: =IFERROR(K4/F4,"") -> 0.18630159 | M4: =IFERROR(K4*1000/H4,"") -> 4230.4932 | N4: =IF(L4="","",RANK(L4,$L$3:$L$168,0)+COUNTIF($L$3:L4,L4)-1) -> 38 | O4: =IF(K4="","",RANK(K4,$K$3:$K$168,0)+COUNTIF($K$3:K4,K4)-1) -> 3 | P4: 4790 | Q4: =IFERROR(P4/AR4,"") -> 0.15899887 | R4: 771 | S4: 3766138 | T4: =IFERROR(S4/F4,"") -> 0.54594069 | U4: =IFERROR(S4*1000/H4,"") -> 12397.094 | V4: =IF(T4="","",RANK(T4,$T$3:$T$168,0)+COUNTIF($T$3:T4,T4)-1) -> 6 | W4: =IF(S4="","",RANK(S4,$S$3:$S$168,0)+COUNTIF($S$3:S4,S4)-1) -> 2 | X4: 9267 | Y4: 15803 | Z4: =IFERROR((X4+Y4)/AR4,"") -> 0.83217155 | AA4: 1662885 | AB4: =IFERROR(AA4/F4,"") -> 0.24105239 | AC4: =IFERROR(AA4*1000/H4,"") -> 5473.7617 | AD4: =IF(AB4="","",RANK(AB4,$AB$3:$AB$168,0)+COUNTIF($AB$3:AB4,AB4)-1) -> 149 | AE4: =IF(AA4="","",RANK(AA4,$AA$3:$AA$168,0)+COUNTIF($AA$3:AA4,AA4)-1) -> 2 | AF4: 66.4 | AG4: 1.455609e+09 | AH4: =IFERROR(AG4/AZ4,"") -> 5501.646 | AI4: 184225 | AJ4: =IFERROR(AI4/F4,"") -> 0.026705321 | AK4: 11354 | AL4: 12753 | AM4: 13622 | AN4: 97192 | AO4: 81997 | AP4: 2 | AQ4: =IFERROR(AL4*1000/AZ4,"") -> 48.201469 | AR4: 30126 | AS4: 13465 | AT4: 12081 | AU4: 1688 | AV4: 2892 | AW4: =IFERROR(AS4/AR4,"") -> 0.44695612 | AX4: 206 | AY4: 50 | AZ4: 264577 | BA4: 2099.334 | BB4: 126.03 | BC4: 0.72 | BD4: 38 | BE4: 98.56 | BF4: 5.9 | BG4: 4.5 | BH4: 52.96 | BI4: 97079 | BJ4: 2 | BK4: =IFERROR(BI4/AZ4,"") -> 0.36692154 | BL4: =IFERROR(AI4+K4+S4+AA4-F4,"") -> 0 | BM4: =IFERROR(F4+G4-C4,"") -> 0 | BN4: =IF(I4="","",IFERROR(C4*1000/H4-I4,"")) -> -0.0033670406
A5: 2403251 | B5: Parnamirim | C5: 6845358 | D5: 7490688 | E5: 7608526 | F5: 5682309 | G5: 1163049 | H5: 272490 | I5: 25121.5 | J5: 30107.02 | K5: 577662 | L5: =IFERROR(K5/F5,"") -> 0.10165973 | M5: =IFERROR(K5*1000/H5,"") -> 2119.9383 | N5: =IF(L5="","",RANK(L5,$L$3:$L$168,0)+COUNTIF($L$3:L5,L5)-1) -> 58 | O5: =IF(K5="","",RANK(K5,$K$3:$K$168,0)+COUNTIF($K$3:K5,K5)-1) -> 5 | P5: 4745 | Q5: =IFERROR(P5/AR5,"") -> 0.14688583 | R5: 594 | S5: 3470184 | T5: =IFERROR(S5/F5,"") -> 0.61069963 | U5: =IFERROR(S5*1000/H5,"") -> 12735.088 | V5: =IF(T5="","",RANK(T5,$T$3:$T$168,0)+COUNTIF($T$3:T5,T5)-1) -> 3 | W5: =IF(S5="","",RANK(S5,$S$3:$S$168,0)+COUNTIF($S$3:S5,S5)-1) -> 3 | X5: 8341 | Y5: 19136 | Z5: =IFERROR((X5+Y5)/AR5,"") -> 0.85057578 | AA5: 1550432 | AB5: =IFERROR(AA5/F5,"") -> 0.27285246 | AC5: =IFERROR(AA5*1000/H5,"") -> 5689.8675 | AD5: =IF(AB5="","",RANK(AB5,$AB$3:$AB$168,0)+COUNTIF($AB$3:AB5,AB5)-1) -> 144 | AE5: =IF(AA5="","",RANK(AA5,$AA$3:$AA$168,0)+COUNTIF($AA$3:AA5,AA5)-1) -> 3 | AF5: 66.9 | AG5: 1.0390884e+09 | AH5: =IFERROR(AG5/AZ5,"") -> 4111.6844 | AI5: 84031 | AJ5: =IFERROR(AI5/F5,"") -> 0.014788179 | AK5: 9215 | AL5: 10058 | AM5: 10479 | AN5: 63485 | AO5: 52323 | AP5: 1.7 | AQ5: =IFERROR(AL5*1000/AZ5,"") -> 39.799617 | AR5: 32304 | AS5: 18863 | AT5: 9552 | AU5: 1403 | AV5: 2486 | AW5: =IFERROR(AS5/AR5,"") -> 0.5839215 | AX5: 63 | AY5: 19 | AZ5: 252716 | BA5: 124.006 | BB5: 2037.93 | BC5: 0.766 | BD5: 35.5 | BE5: 98.96 | BF5: 5.1 | BG5: 4 | BH5: 16.04 | BI5: 63416 | BJ5: 1.7 | BK5: =IFERROR(BI5/AZ5,"") -> 0.25093781 | BL5: =IFERROR(AI5+K5+S5+AA5-F5,"") -> 0 | BM5: =IFERROR(F5+G5-C5,"") -> 0 | BN5: =IF(I5="","",IFERROR(C5*1000/H5-I5,"")) -> 0.0017064846
A6: 2404507 | B6: Guamaré | C6: 2042133 | D6: 2748777 | E6: 2581922 | F6: 1961362 | G6: 80771 | H6: 16261 | I6: 125584.68 | J6: 168808.24 | K6: 1471020 | L6: =IFERROR(K6/F6,"") -> 0.74999924 | M6: =IFERROR(K6*1000/H6,"") -> 90463.071 | N6: =IF(L6="","",RANK(L6,$L$3:$L$168,0)+COUNTIF($L$3:L6,L6)-1) -> 5 | O6: =IF(K6="","",RANK(K6,$K$3:$K$168,0)+COUNTIF($K$3:K6,K6)-1) -> 2 | P6: 153 | Q6: =IFERROR(P6/AR6,"") -> 0.13385827 | R6: 38 | S6: 258287 | T6: =IFERROR(S6/F6,"") -> 0.13168757 | U6: =IFERROR(S6*1000/H6,"") -> 15883.832 | V6: =IF(T6="","",RANK(T6,$T$3:$T$168,0)+COUNTIF($T$3:T6,T6)-1) -> 156 | W6: =IF(S6="","",RANK(S6,$S$3:$S$168,0)+COUNTIF($S$3:S6,S6)-1) -> 15 | X6: 392 | Y6: 577 | Z6: =IFERROR((X6+Y6)/AR6,"") -> 0.84776903 | AA6: 190763 | AB6: =IFERROR(AA6/F6,"") -> 0.097260475 | AC6: =IFERROR(AA6*1000/H6,"") -> 11731.32 | AD6: =IF(AB6="","",RANK(AB6,$AB$3:$AB$168,0)+COUNTIF($AB$3:AB6,AB6)-1) -> 163 | AE6: =IF(AA6="","",RANK(AA6,$AA$3:$AA$168,0)+COUNTIF($AA$3:AA6,AA6)-1) -> 17 | AF6: 77.94 | AG6: 2.6248183e+08 | AH6: =IFERROR(AG6/AZ6,"") -> 17161.284 | AI6: 41293 | AJ6: =IFERROR(AI6/F6,"") -> 0.021053227 | AK6: 437 | AL6: 475 | AM6: 492 | AN6: 2826 | AO6: 2423 | AP6: 3.6 | AQ6: =IFERROR(AL6*1000/AZ6,"") -> 31.055901 | AR6: 1143 | AS6: 579 | AT6: 364 | AU6: 27 | AV6: 173 | AW6: =IFERROR(AS6/AR6,"") -> 0.50656168 | AX6: 14 | AY6: 6 | AZ6: 15295 | BA6: 258.307 | BB6: 59.21 | BC6: 0.626 | BD6: 44 | BE6: 98.86 | BF6: 5.5 | BG6: 4 | BH6: 26.34 | BI6: 2826 | BJ6: 3.6 | BK6: =IFERROR(BI6/AZ6,"") -> 0.18476626 | BL6: =IFERROR(AI6+K6+S6+AA6-F6,"") -> 1 | BM6: =IFERROR(F6+G6-C6,"") -> 0 | BN6: =IF(I6="","",IFERROR(C6*1000/H6-I6,"")) -> 0.031887338
A7: 2412005 | B7: São Gonçalo do Amarante | C7: 1905641 | D7: 2307194 | E7: 2588564 | F7: 1675162 | G7: 230479 | H7: 104919 | I7: 18162.97 | J7: 22346.41 | K7: 169638 | L7: =IFERROR(K7/F7,"") -> 0.10126662 | M7: =IFERROR(K7*1000/H7,"") -> 1616.8473 | N7: =IF(L7="","",RANK(L7,$L$3:$L$168,0)+COUNTIF($L$3:L7,L7)-1) -> 59 | O7: =IF(K7="","",RANK(K7,$K$3:$K$168,0)+COUNTIF($K$3:K7,K7)-1) -> 21 | P7: 1814 | Q7: =IFERROR(P7/AR7,"") -> 0.19271221 | R7: 266 | S7: 878071 | T7: =IFERROR(S7/F7,"") -> 0.5241708 | U7: =IFERROR(S7*1000/H7,"") -> 8369.0371 | V7: =IF(T7="","",RANK(T7,$T$3:$T$168,0)+COUNTIF($T$3:T7,T7)-1) -> 7 | W7: =IF(S7="","",RANK(S7,$S$3:$S$168,0)+COUNTIF($S$3:S7,S7)-1) -> 4 | X7: 2594 | Y7: 4935 | Z7: =IFERROR((X7+Y7)/AR7,"") -> 0.79985127 | AA7: 589005 | AB7: =IFERROR(AA7/F7,"") -> 0.35161077 | AC7: =IFERROR(AA7*1000/H7,"") -> 5613.9022 | AD7: =IF(AB7="","",RANK(AB7,$AB$3:$AB$168,0)+COUNTIF($AB$3:AB7,AB7)-1) -> 132 | AE7: =IF(AA7="","",RANK(AA7,$AA$3:$AA$168,0)+COUNTIF($AA$3:AA7,AA7)-1) -> 4 | AF7: 61.26 | AG7: 6.2110339e+08 | AH7: =IFERROR(AG7/AZ7,"") -> 5361.8276 | AI7: 38448 | AJ7: =IFERROR(AI7/F7,"") -> 0.02295181 | AK7: 1936 | AL7: 2232 | AM7: 2404 | AN7: 17939 | AO7: 15602 | AP7: 1.7 | AQ7: =IFERROR(AL7*1000/AZ7,"") -> 19.268288 | AR7: 9413 | AS7: 6050 | AT7: 2301 | AU7: 354 | AV7: 708 | AW7: =IFERROR(AS7/AR7,"") -> 0.64272814 | AX7: 56 | AY7: 14 | AZ7: 115838 | BA7: 249.8 | BB7: 463.72 | BC7: 0.661 | BD7: 41.3 | BE7: 99.02 | BF7: 4.7 | BG7: 3.8 | BH7: 32.73 | BI7: 17939 | BJ7: 1.7 | BK7: =IFERROR(BI7/AZ7,"") -> 0.15486283 | BL7: =IFERROR(AI7+K7+S7+AA7-F7,"") -> 0 | BM7: =IFERROR(F7+G7-C7,"") -> 0 | BN7: =IF(I7="","",IFERROR(C7*1000/H7-I7,"")) -> 0.0033413395
A8: 2407104 | B8: Macaíba | C8: 1828142 | D8: 2109145 | E8: 2455739 | F8: 1561048 | G8: 267094 | H8: 82828 | I8: 22071.55 | J8: 29857.38 | K8: 485851 | L8: =IFERROR(K8/F8,"") -> 0.31123386 | M8: =IFERROR(K8*1000/H8,"") -> 5865.7821 | N8: =IF(L8="","",RANK(L8,$L$3:$L$168,0)+COUNTIF($L$3:L8,L8)-1) -> 26 | O8: =IF(K8="","",RANK(K8,$K$3:$K$168,0)+COUNTIF($K$3:K8,K8)-1) -> 9 | P8: 1396 | Q8: =IFERROR(P8/AR8,"") -> 0.25085355 | R8: 376 | S8: 605895 | T8: =IFERROR(S8/F8,"") -> 0.38813348 | U8: =IFERROR(S8*1000/H8,"") -> 7315.0988 | V8: =IF(T8="","",RANK(T8,$T$3:$T$168,0)+COUNTIF($T$3:T8,T8)-1) -> 29 | W8: =IF(S8="","",RANK(S8,$S$3:$S$168,0)+COUNTIF($S$3:S8,S8)-1) -> 6 | X8: 1642 | Y8: 2451 | Z8: =IFERROR((X8+Y8)/AR8,"") -> 0.73548967 | AA8: 433168 | AB8: =IFERROR(AA8/F8,"") -> 0.27748538 | AC8: =IFERROR(AA8*1000/H8,"") -> 5229.7291 | AD8: =IF(AB8="","",RANK(AB8,$AB$3:$AB$168,0)+COUNTIF($AB$3:AB8,AB8)-1) -> 142 | AE8: =IF(AA8="","",RANK(AA8,$AA$3:$AA$168,0)+COUNTIF($AA$3:AA8,AA8)-1) -> 5 | AF8: 73.11 | AG8: 4.1173966e+08 | AH8: =IFERROR(AG8/AZ8,"") -> 5006.0142 | AI8: 36133 | AJ8: =IFERROR(AI8/F8,"") -> 0.02314663 | AK8: 1766 | AL8: 1886 | AM8: 2286 | AN8: 14258 | AO8: 12208 | AP8: 1.9 | AQ8: =IFERROR(AL8*1000/AZ8,"") -> 22.93037 | AR8: 5565 | AS8: 2758 | AT8: 1826 | AU8: 268 | AV8: 713 | AW8: =IFERROR(AS8/AR8,"") -> 0.49559748 | AX8: 59 | AY8: 17 | AZ8: 82249 | BA8: 510.092 | BB8: 161.24 | BC8: 0.64 | BD8: 44.5 | BE8: 96.89 | BF8: 5 | BG8: 4.1 | BH8: 10.23 | BI8: 14239 | BJ8: 1.9 | BK8: =IFERROR(BI8/AZ8,"") -> 0.17312065 | BL8: =IFERROR(AI8+K8+S8+AA8-F8,"") -> -1 | BM8: =IFERROR(F8+G8-C8,"") -> 0 | BN8: =IF(I8="","",IFERROR(C8*1000/H8-I8,"")) -> -0.004145941
A9: 2400208 | B9: Assú | C9: 1467562 | D9: 2146108 | E9: 2170177 | F9: 1368136 | G9: 99426 | H9: 58743 | I9: 24982.76 | J9: 38412.94 | K9: 483176 | L9: =IFERROR(K9/F9,"") -> 0.35316372 | M9: =IFERROR(K9*1000/H9,"") -> 8225.2524 | N9: =IF(L9="","",RANK(L9,$L$3:$L$168,0)+COUNTIF($L$3:L9,L9)-1) -> 22 | O9: =IF(K9="","",RANK(K9,$K$3:$K$168,0)+COUNTIF($K$3:K9,K9)-1) -> 10 | P9: 676 | Q9: =IFERROR(P9/AR9,"") -> 0.15486827 | R9: 145 | S9: 518977 | T9: =IFERROR(S9/F9,"") -> 0.37933144 | U9: =IFERROR(S9*1000/H9,"") -> 8834.7037 | V9: =IF(T9="","",RANK(T9,$T$3:$T$168,0)+COUNTIF($T$3:T9,T9)-1) -> 30 | W9: =IF(S9="","",RANK(S9,$S$3:$S$168,0)+COUNTIF($S$3:S9,S9)-1) -> 7 | X9: 1563 | Y9: 2061 | Z9: =IFERROR((X9+Y9)/AR9,"") -> 0.83024055 | AA9: 330939 | AB9: =IFERROR(AA9/F9,"") -> 0.24189043 | AC9: =IFERROR(AA9*1000/H9,"") -> 5633.6755 | AD9: =IF(AB9="","",RANK(AB9,$AB$3:$AB$168,0)+COUNTIF($AB$3:AB9,AB9)-1) -> 148 | AE9: =IF(AA9="","",RANK(AA9,$AA$3:$AA$168,0)+COUNTIF($AA$3:AA9,AA9)-1) -> 8 | AF9: 77.19 | AG9: 3.2855936e+08 | AH9: =IFERROR(AG9/AZ9,"") -> 5815.6217 | AI9: 35044 | AJ9: =IFERROR(AI9/F9,"") -> 0.025614413 | AK9: 1744 | AL9: 1969 | AM9: 2065 | AN9: 9666 | AO9: 7528 | AP9: 1.8 | AQ9: =IFERROR(AL9*1000/AZ9,"") -> 34.852025 | AR9: 4365 | AS9: 1897 | AT9: 1761 | AU9: 221 | AV9: 486 | AW9: =IFERROR(AS9/AR9,"") -> 0.43459336 | AX9: 53 | AY9: 12 | AZ9: 56496 | BA9: 1303.442 | BB9: 43.34 | BC9: 0.661 | BD9: 44.7 | BE9: 98.04 | BF9: 4.8 | BG9: 3.7 | BH9: 2.6 | BI9: 9658 | BJ9: 1.8 | BK9: =IFERROR(BI9/AZ9,"") -> 0.17095016 | BL9: =IFERROR(AI9+K9+S9+AA9-F9,"") -> 0 | BM9: =IFERROR(F9+G9-C9,"") -> 0 | BN9: =IF(I9="","",IFERROR(C9*1000/H9-I9,"")) -> -0.0046078682
A10: 2402006 | B10: Caicó | C10: 1394838 | D10: 1598739 | E10: 1735797 | F10: 1214573 | G10: 180265 | H10: 68726 | I10: 20295.64 | J10: 28387.75 | K10: 80879 | L10: =IFERROR(K10/F10,"") -> 0.066590481 | M10: =IFERROR(K10*1000/H10,"") -> 1176.8326 | N10: =IF(L10="","",RANK(L10,$L$3:$L$168,0)+COUNTIF($L$3:L10,L10)-1) -> 73 | O10: =IF(K10="","",RANK(K10,$K$3:$K$168,0)+COUNTIF($K$3:K10,K10)-1) -> 31 | P10: 1073 | Q10: =IFERROR(P10/AR10,"") -> 0.1657911 | R10: 94 | S10: 687110 | T10: =IFERROR(S10/F10,"") -> 0.56572145 | U10: =IFERROR(S10*1000/H10,"") -> 9997.8174 | V10: =IF(T10="","",RANK(T10,$T$3:$T$168,0)+COUNTIF($T$3:T10,T10)-1) -> 5 | W10: =IF(S10="","",RANK(S10,$S$3:$S$168,0)+COUNTIF($S$3:S10,S10)-1) -> 5 | X10: 2247 | Y10: 3119 | Z10: =IFERROR((X10+Y10)/AR10,"") -> 0.82911001 | AA10: 392190 | AB10: =IFERROR(AA10/F10,"") -> 0.3229036 | AC10: =IFERROR(AA10*1000/H10,"") -> 5706.5739 | AD10: =IF(AB10="","",RANK(AB10,$AB$3:$AB$168,0)+COUNTIF($AB$3:AB10,AB10)-1) -> 134 | AE10: =IF(AA10="","",RANK(AA10,$AA$3:$AA$168,0)+COUNTIF($AA$3:AA10,AA10)-1) -> 7 | AF10: 81.82 | AG10: 2.9794052e+08 | AH10: =IFERROR(AG10/AZ10,"") -> 4872.6086 | AI10: 54394 | AJ10: =IFERROR(AI10/F10,"") -> 0.044784463 | AK10: 2147 | AL10: 2404 | AM10: 2584 | AN10: 14370 | AO10: 11540 | AP10: 1.7 | AQ10: =IFERROR(AL10*1000/AZ10,"") -> 39.315736 | AR10: 6472 | AS10: 3345 | AT10: 2346 | AU10: 245 | AV10: 536 | AW10: =IFERROR(AS10/AR10,"") -> 0.51684178 | AX10: 15 | AY10: 15 | AZ10: 61146 | BA10: 1228.583 | BB10: 49.77 | BC10: 0.71 | BD10: 37.9 | BE10: 98.92 | BF10: 5.9 | BG10: 4.6 | BH10: 73.59 | BI10: 14370 | BJ10: 1.7 | BK10: =IFERROR(BI10/AZ10,"") -> 0.23501128 | BL10: =IFERROR(AI10+K10+S10+AA10-F10,"") -> 0 | BM10: =IFERROR(F10+G10-C10,"") -> 0 | BN10: =IF(I10="","",IFERROR(C10*1000/H10-I10,"")) -> -0.0022500946
A11: 2405801 | B11: João Câmara | C11: 1269833 | D11: 1419596 | E11: 1527022 | F11: 1197893 | G11: 71940 | H11: 35360 | I11: 35911.56 | J11: 45870.29 | K11: 712023 | L11: =IFERROR(K11/F11,"") -> 0.59439616 | M11: =IFERROR(K11*1000/H11,"") -> 20136.397 | N11: =IF(L11="","",RANK(L11,$L$3:$L$168,0)+COUNTIF($L$3:L11,L11)-1) -> 9 | O11: =IF(K11="","",RANK(K11,$K$3:$K$168,0)+COUNTIF($K$3:K11,K11)-1) -> 4 | P11: 388 | Q11: =IFERROR(P11/AR11,"") -> 0.14526395 | R11: 84 | S11: 241850 | T11: =IFERROR(S11/F11,"") -> 0.20189616 | U11: =IFERROR(S11*1000/H11,"") -> 6839.6493 | V11: =IF(T11="","",RANK(T11,$T$3:$T$168,0)+COUNTIF($T$3:T11,T11)-1) -> 141 | W11: =IF(S11="","",RANK(S11,$S$3:$S$168,0)+COUNTIF($S$3:S11,S11)-1) -> 16 | X11: 1008 | Y11: 1246 | Z11: =IFERROR((X11+Y11)/AR11,"") -> 0.8438787 | AA11: 222640 | AB11: =IFERROR(AA11/F11,"") -> 0.18585967 | AC11: =IFERROR(AA11*1000/H11,"") -> 6296.3801 | AD11: =IF(AB11="","",RANK(AB11,$AB$3:$AB$168,0)+COUNTIF($AB$3:AB11,AB11)-1) -> 156 | AE11: =IF(AA11="","",RANK(AA11,$AA$3:$AA$168,0)+COUNTIF($AA$3:AA11,AA11)-1) -> 12 | AF11: 74.37 | AG11: 2.3548284e+08 | AH11: =IFERROR(AG11/AZ11,"") -> 7073.681 | AI11: 21379 | AJ11: =IFERROR(AI11/F11,"") -> 0.01784717 | AK11: 964 | AL11: 1049 | AM11: 1089 | AN11: 4713 | AO11: 3696 | AP11: 2.1 | AQ11: =IFERROR(AL11*1000/AZ11,"") -> 31.510964 | AR11: 2671 | AS11: 1319 | AT11: 966 | AU11: 106 | AV11: 280 | AW11: =IFERROR(AS11/AR11,"") -> 0.49382254 | AX11: 20 | AY11: 9 | AZ11: 33290 | BA11: 714.971 | BB11: 46.56 | BC11: 0.595 | BD11: 48 | BE11: 97.61 | BF11: 4.6 | BG11: 3.7 | BH11: 30.28 | BI11: 4713 | BJ11: 2.1 | BK11: =IFERROR(BI11/AZ11,"") -> 0.14157405 | BL11: =IFERROR(AI11+K11+S11+AA11-F11,"") -> -1 | BM11: =IFERROR(F11+G11-C11,"") -> 0 | BN11: =IF(I11="","",IFERROR(C11*1000/H11-I11,"")) -> 0.0067420815
A12: 2407203 | B12: Macau | C12: 1111118 | D12: 1493271 | E12: 1315680 | F12: 1065640 | G12: 45478 | H12: 32260 | I12: 34442.58 | J12: 48071.89 | K12: 546975 | L12: =IFERROR(K12/F12,"") -> 0.5132831 | M12: =IFERROR(K12*1000/H12,"") -> 16955.208 | N12: =IF(L12="","",RANK(L12,$L$3:$L$168,0)+COUNTIF($L$3:L12,L12)-1) -> 11 | O12: =IF(K12="","",RANK(K12,$K$3:$K$168,0)+COUNTIF($K$3:K12,K12)-1) -> 7 | P12: 310 | Q12: =IFERROR(P12/AR12,"") -> 0.14065336 | R12: 45 | S12: 290912 | T12: =IFERROR(S12/F12,"") -> 0.27299276 | U12: =IFERROR(S12*1000/H12,"") -> 9017.7309 | V12: =IF(T12="","",RANK(T12,$T$3:$T$168,0)+COUNTIF($T$3:T12,T12)-1) -> 73 | W12: =IF(S12="","",RANK(S12,$S$3:$S$168,0)+COUNTIF($S$3:S12,S12)-1) -> 12 | X12: 874 | Y12: 971 | Z12: =IFERROR((X12+Y12)/AR12,"") -> 0.83711434 | AA12: 186985 | AB12: =IFERROR(AA12/F12,"") -> 0.17546732 | AC12: =IFERROR(AA12*1000/H12,"") -> 5796.1872 | AD12: =IF(AB12="","",RANK(AB12,$AB$3:$AB$168,0)+COUNTIF($AB$3:AB12,AB12)-1) -> 157 | AE12: =IF(AA12="","",RANK(AA12,$AA$3:$AA$168,0)+COUNTIF($AA$3:AA12,AA12)-1) -> 19 | AF12: 90.23 | AG12: 1.8943428e+08 | AH12: =IFERROR(AG12/AZ12,"") -> 6921.4908 | AI12: 40768 | AJ12: =IFERROR(AI12/F12,"") -> 0.038256822 | AK12: 811 | AL12: 836 | AM12: 870 | AN12: 5173 | AO12: 4327 | AP12: 2.4 | AQ12: =IFERROR(AL12*1000/AZ12,"") -> 30.545508 | AR12: 2204 | AS12: 1181 | AT12: 700 | AU12: 76 | AV12: 247 | AW12: =IFERROR(AS12/AR12,"") -> 0.53584392 | AX12: 38 | AY12: 11 | AZ12: 27369 | BA12: 775.302 | BB12: 35.3 | BC12: 0.665 | BD12: 42.8 | BE12: 99.18 | BF12: 5.5 | BG12: 4.3 | BH12: 57.41 | BI12: 5160 | BJ12: 2.4 | BK12: =IFERROR(BI12/AZ12,"") -> 0.18853447 | BL12: =IFERROR(AI12+K12+S12+AA12-F12,"") -> 0 | BM12: =IFERROR(F12+G12-C12,"") -> 0 | BN12: =IF(I12="","",IFERROR(C12*1000/H12-I12,"")) -> 0.011444513
A13: 2412203 | B13: São José de Mipibu | C13: 1040956 | D13: 1359848 | E13: 1457800 | F13: 878691 | G13: 162265 | H13: 44566 | I13: 23357.62 | J13: 30829.42 | K13: 122526 | L13: =IFERROR(K13/F13,"") -> 0.13944151 | M13: =IFERROR(K13*1000/H13,"") -> 2749.3156 | N13: =IF(L13="","",RANK(L13,$L$3:$L$168,0)+COUNTIF($L$3:L13,L13)-1) -> 49 | O13: =IF(K13="","",RANK(K13,$K$3:$K$168,0)+COUNTIF($K$3:K13,K13)-1) -> 23 | P13: 676 | Q13: =IFERROR(P13/AR13,"") -> 0.18576532 | R13: 164 | S13: 435717 | T13: =IFERROR(S13/F13,"") -> 0.49587056 | U13: =IFERROR(S13*1000/H13,"") -> 9776.8927 | V13: =IF(T13="","",RANK(T13,$T$3:$T$168,0)+COUNTIF($T$3:T13,T13)-1) -> 9 | W13: =IF(S13="","",RANK(S13,$S$3:$S$168,0)+COUNTIF($S$3:S13,S13)-1) -> 8 | X13: 1240 | Y13: 1660 | Z13: =IFERROR((X13+Y13)/AR13,"") -> 0.79692223 | AA13: 261506 | AB13: =IFERROR(AA13/F13,"") -> 0.2976086 | AC13: =IFERROR(AA13*1000/H13,"") -> 5867.8365 | AD13: =IF(AB13="","",RANK(AB13,$AB$3:$AB$168,0)+COUNTIF($AB$3:AB13,AB13)-1) -> 136 | AE13: =IF(AA13="","",RANK(AA13,$AA$3:$AA$168,0)+COUNTIF($AA$3:AA13,AA13)-1) -> 9 | AF13: 90.1 | AG13: 2.8549701e+08 | AH13: =IFERROR(AG13/AZ13,"") -> 6037.6646 | AI13: 58942 | AJ13: =IFERROR(AI13/F13,"") -> 0.067079326 | AK13: 1089 | AL13: 1204 | AM13: 1298 | AN13: 9918 | AO13: 8676 | AP13: 1.7 | AQ13: =IFERROR(AL13*1000/AZ13,"") -> 25.462082 | AR13: 3639 | AS13: 1973 | AT13: 1139 | AU13: 148 | AV13: 379 | AW13: =IFERROR(AS13/AR13,"") -> 0.54218192 | AX13: 50 | AY13: 13 | AZ13: 47286 | BA13: 289.987 | BB13: 163.06 | BC13: 0.611 | BD13: 48.2 | BE13: 98.35 | BF13: 5.2 | BG13: 3.7 | BH13: 4.85 | BI13: 9918 | BJ13: 1.7 | BK13: =IFERROR(BI13/AZ13,"") -> 0.20974496 | BL13: =IFERROR(AI13+K13+S13+AA13-F13,"") -> 0 | BM13: =IFERROR(F13+G13-C13,"") -> 0 | BN13: =IF(I13="","",IFERROR(C13*1000/H13-I13,"")) -> 0.0068904546
A14: 2402600 | B14: Ceará-Mirim | C14: 1002193 | D14: 1186374 | E14: 1260346 | F14: 904757 | G14: 97436 | H14: 74268 | I14: 13494.28 | J14: 15930.56 | K14: 45712 | L14: =IFERROR(K14/F14,"") -> 0.050524063 | M14: =IFERROR(K14*1000/H14,"") -> 615.50062 | N14: =IF(L14="","",RANK(L14,$L$3:$L$168,0)+COUNTIF($L$3:L14,L14)-1) -> 88 | O14: =IF(K14="","",RANK(K14,$K$3:$K$168,0)+COUNTIF($K$3:K14,K14)-1) -> 40 | P14: 790 | Q14: =IFERROR(P14/AR14,"") -> 0.1823638 | R14: 165 | S14: 365315 | T14: =IFERROR(S14/F14,"") -> 0.4037714 | U14: =IFERROR(S14*1000/H14,"") -> 4918.8749 | V14: =IF(T14="","",RANK(T14,$T$3:$T$168,0)+COUNTIF($T$3:T14,T14)-1) -> 26 | W14: =IF(S14="","",RANK(S14,$S$3:$S$168,0)+COUNTIF($S$3:S14,S14)-1) -> 10 | X14: 1557 | Y14: 1891 | Z14: =IFERROR((X14+Y14)/AR14,"") -> 0.79593721 | AA14: 419272 | AB14: =IFERROR(AA14/F14,"") -> 0.46340841 | AC14: =IFERROR(AA14*1000/H14,"") -> 5645.3924 | AD14: =IF(AB14="","",RANK(AB14,$AB$3:$AB$168,0)+COUNTIF($AB$3:AB14,AB14)-1) -> 100 | AE14: =IF(AA14="","",RANK(AA14,$AA$3:$AA$168,0)+COUNTIF($AA$3:AA14,AA14)-1) -> 6 | AF14: 74.58 | AG14: 3.9459177e+08 | AH14: =IFERROR(AG14/AZ14,"") -> 4987.5722 | AI14: 74458 | AJ14: =IFERROR(AI14/F14,"") -> 0.08229613 | AK14: 1329 | AL14: 1475 | AM14: 1639 | AN14: 8956 | AO14: 7325 | AP14: 1.7 | AQ14: =IFERROR(AL14*1000/AZ14,"") -> 18.643746 | AR14: 4332 | AS14: 2265 | AT14: 1387 | AU14: 252 | AV14: 428 | AW14: =IFERROR(AS14/AR14,"") -> 0.52285319 | AX14: 78 | AY14: 16 | AZ14: 79115 | BA14: 724.838 | BB14: 109.15 | BC14: 0.616 | BD14: 46.1 | BE14: 98 | BF14: 4.5 | BG14: 3.7 | BH14: 24.78 | BI14: 8956 | BJ14: 1.7 | BK14: =IFERROR(BI14/AZ14,"") -> 0.1132023 | BL14: =IFERROR(AI14+K14+S14+AA14-F14,"") -> 0 | BM14: =IFERROR(F14+G14-C14,"") -> 0 | BN14: =IF(I14="","",IFERROR(C14*1000/H14-I14,"")) -> -0.0025184467
... A42: 2409506 | B42: Pedra Grande | C42: 293283 | D42: 243846 | E42: 325405 | F42: 273296 | G42: 19986 | H42: 3163 | I42: 92722.93 | J42: 89940.55 | K42: 213403 | L42: =IFERROR(K42/F42,"") -> 0.78084934 | M42: =IFERROR(K42*1000/H42,"") -> 67468.543 | N42: =IF(L42="","",RANK(L42,$L$3:$L$168,0)+COUNTIF($L$3:L42,L42)-1) -> 4 | O42: =IF(K42="","",RANK(K42,$K$3:$K$168,0)+COUNTIF($K$3:K42,K42)-1) -> 18 | P42: 43 | Q42: =IFERROR(P42/AR42,"") -> 0.21827411 | R42: 27 | S42: 18822 | T42: =IFERROR(S42/F42,"") -> 0.068870382 | U42: =IFERROR(S42*1000/H42,"") -> 5950.6797 | V42: =IF(T42="","",RANK(T42,$T$3:$T$168,0)+COUNTIF($T$3:T42,T42)-1) -> 163 | W42: =IF(S42="","",RANK(S42,$S$3:$S$168,0)+COUNTIF($S$3:S42,S42)-1) -> 106 | X42: 57 | Y42: 87 | Z42: =IFERROR((X42+Y42)/AR42,"") -> 0.73096447 | AA42: 33888 | AB42: =IFERROR(AA42/F42,"") -> 0.12399742 | AC42: =IFERROR(AA42*1000/H42,"") -> 10713.879 | AD42: =IF(AB42="","",RANK(AB42,$AB$3:$AB$168,0)+COUNTIF($AB$3:AB42,AB42)-1) -> 161 | AE42: =IF(AA42="","",RANK(AA42,$AA$3:$AA$168,0)+COUNTIF($AA$3:AA42,AA42)-1) -> 120 | AF42: 90.01 | AG42: 58690869 | AH42: =IFERROR(AG42/AZ42,"") -> 16221.91 | AI42: 7183 | AJ42: =IFERROR(AI42/F42,"") -> 0.026282858 | AK42: 88 | AL42: 101 | AM42: 101 | AN42: 438 | AO42: 349 | AP42: 2.4 | AQ42: =IFERROR(AL42*1000/AZ42,"") -> 27.915976 | AR42: 197 | AS42: 69 | AT42: 48 | AU42: 2 | AV42: 78 | AW42: =IFERROR(AS42/AR42,"") -> 0.35025381 | AX42: 3 | AY42: 7 | AZ42: 3618 | BA42: 221.167 | BB42: 16.36 | BC42: 0.559 | BD42: 55 | BE42: 99.26 | BF42: 5 | BG42: 4.1 | BH42: 0.81 | BI42: 438 | BJ42: 2.4 | BK42: =IFERROR(BI42/AZ42,"") -> 0.12106136 | BL42: =IFERROR(AI42+K42+S42+AA42-F42,"") -> 0 | BM42: =IFERROR(F42+G42-C42,"") -> -1 | BN42: =IF(I42="","",IFERROR(C42*1000/H42-I42,"")) -> 0.11773949
A43: 2401651 | B43: Bodó | C43: 286574 | D43: 229572 | E43: 240166 | F43: 283980 | G43: 2593 | H43: 2171 | I43: 132000.71 | J43: 104148.52 | K43: 246251 | L43: =IFERROR(K43/F43,"") -> 0.86714205 | M43: =IFERROR(K43*1000/H43,"") -> 113427.45 | N43: =IF(L43="","",RANK(L43,$L$3:$L$168,0)+COUNTIF($L$3:L43,L43)-1) -> 3 | O43: =IF(K43="","",RANK(K43,$K$3:$K$168,0)+COUNTIF($K$3:K43,K43)-1) -> 16 | P43: 37 | Q43: =IFERROR(P43/AR43,"") -> 0.22424242 | R43: 24 | S43: 9465 | T43: =IFERROR(S43/F43,"") -> 0.033329812 | U43: =IFERROR(S43*1000/H43,"") -> 4359.7421 | V43: =IF(T43="","",RANK(T43,$T$3:$T$168,0)+COUNTIF($T$3:T43,T43)-1) -> 166 | W43: =IF(S43="","",RANK(S43,$S$3:$S$168,0)+COUNTIF($S$3:S43,S43)-1) -> 149 | X43: 32 | Y43: 89 | Z43: =IFERROR((X43+Y43)/AR43,"") -> 0.73333333 | AA43: 24181 | AB43: =IFERROR(AA43/F43,"") -> 0.085150363 | AC43: =IFERROR(AA43*1000/H43,"") -> 11138.185 | AD43: =IF(AB43="","",RANK(AB43,$AB$3:$AB$168,0)+COUNTIF($AB$3:AB43,AB43)-1) -> 164 | AE43: =IF(AA43="","",RANK(AA43,$AA$3:$AA$168,0)+COUNTIF($AA$3:AA43,AA43)-1) -> 153 | AF43: 69.91 | AG43: 53841631 | AH43: =IFERROR(AG43/AZ43,"") -> 23348.496 | AI43: 4083 | AJ43: =IFERROR(AI43/F43,"") -> 0.014377773 | AK43: 77 | AL43: 120 | AM43: 123 | AN43: 353 | AO43: 257 | AP43: 2.1 | AQ43: =IFERROR(AL43*1000/AZ43,"") -> 52.038161 | AR43: 165 | AS43: 55 | AT43: 21 | AU43: 6 | AV43: 83 | AW43: =IFERROR(AS43/AR43,"") -> 0.33333333 | AX43: 1 | AY43: 6 | AZ43: 2306 | BA43: 253.519 | BB43: 9.1 | BC43: 0.629 | BD43: 52.4 | BE43: 99 | BF43: 5.3 | BH43: 8.93 | BI43: 353 | BJ43: 2.1 | BK43: =IFERROR(BI43/AZ43,"") -> 0.15307892 | BL43: =IFERROR(AI43+K43+S43+AA43-F43,"") -> 0 | BM43: =IFERROR(F43+G43-C43,"") -> -1 | BN43: =IF(I43="","",IFERROR(C43*1000/H43-I43,"")) -> 0.21123445
A44: 2407807 | B44: Monte Alegre | C44: 271451 | D44: 325278 | E44: 348751 | F44: 252958 | G44: 18493 | H44: 22698 | I44: 11959.26 | J44: 15142.66 | K44: 23674 | L44: =IFERROR(K44/F44,"") -> 0.093588659 | M44: =IFERROR(K44*1000/H44,"") -> 1042.9994 | N44: =IF(L44="","",RANK(L44,$L$3:$L$168,0)+COUNTIF($L$3:L44,L44)-1) -> 61 | O44: =IF(K44="","",RANK(K44,$K$3:$K$168,0)+COUNTIF($K$3:K44,K44)-1) -> 53 | P44: 169 | Q44: =IFERROR(P44/AR44,"") -> 0.15943396 | R44: 22 | S44: 78453 | T44: =IFERROR(S44/F44,"") -> 0.3101424 | U44: =IFERROR(S44*1000/H44,"") -> 3456.3838 | V44: =IF(T44="","",RANK(T44,$T$3:$T$168,0)+COUNTIF($T$3:T44,T44)-1) -> 51 | W44: =IF(S44="","",RANK(S44,$S$3:$S$168,0)+COUNTIF($S$3:S44,S44)-1) -> 36 | X44: 385 | Y44: 473 | Z44: =IFERROR((X44+Y44)/AR44,"") -> 0.80943396 | AA44: 136183 | AB44: =IFERROR(AA44/F44,"") -> 0.5383621 | AC44: =IFERROR(AA44*1000/H44,"") -> 5999.7797 | AD44: =IF(AB44="","",RANK(AB44,$AB$3:$AB$168,0)+COUNTIF($AB$3:AB44,AB44)-1) -> 75 | AE44: =IF(AA44="","",RANK(AA44,$AA$3:$AA$168,0)+COUNTIF($AA$3:AA44,AA44)-1) -> 27 | AF44: 85.02 | AG44: 1.5496355e+08 | AH44: =IFERROR(AG44/AZ44,"") -> 6728.477 | AI44: 14648 | AJ44: =IFERROR(AI44/F44,"") -> 0.057906846 | AK44: 328 | AL44: 374 | AM44: 389 | AN44: 2136 | AO44: 1754 | AP44: 1.9 | AQ44: =IFERROR(AL44*1000/AZ44,"") -> 16.238982 | AR44: 1060 | AS44: 538 | AT44: 352 | AU44: 40 | AV44: 130 | AW44: =IFERROR(AS44/AR44,"") -> 0.50754717 | AX44: 22 | AY44: 11 | AZ44: 23031 | BA44: 211.259 | BB44: 109.02 | BC44: 0.609 | BD44: 50.6 | BE44: 97.97 | BF44: 5 | BG44: 4.6 | BH44: 10.3 | BI44: 2136 | BJ44: 1.9 | BK44: =IFERROR(BI44/AZ44,"") -> 0.092744562 | BL44: =IFERROR(AI44+K44+S44+AA44-F44,"") -> 0 | BM44: =IFERROR(F44+G44-C44,"") -> 0 | BN44: =IF(I44="","",IFERROR(C44*1000/H44-I44,"")) -> -0.012489206
A45: 2406502 | B45: Lagoa Nova | C45: 269032 | D45: 291874 | E45: 326107 | F45: 236730 | G45: 32302 | H45: 15880 | I45: 16941.59 | J45: 20940.54 | K45: 77170 | L45: =IFERROR(K45/F45,"") -> 0.32598319 | M45: =IFERROR(K45*1000/H45,"") -> 4859.5718 | N45: =IF(L45="","",RANK(L45,$L$3:$L$168,0)+COUNTIF($L$3:L45,L45)-1) -> 24 | O45: =IF(K45="","",RANK(K45,$K$3:$K$168,0)+COUNTIF($K$3:K45,K45)-1) -> 34 | P45: 200 | Q45: =IFERROR(P45/AR45,"") -> 0.18709074 | R45: 75 | S45: 47028 | T45: =IFERROR(S45/F45,"") -> 0.1986567 | U45: =IFERROR(S45*1000/H45,"") -> 2961.461 | V45: =IF(T45="","",RANK(T45,$T$3:$T$168,0)+COUNTIF($T$3:T45,T45)-1) -> 144 | W45: =IF(S45="","",RANK(S45,$S$3:$S$168,0)+COUNTIF($S$3:S45,S45)-1) -> 51 | X45: 420 | Y45: 433 | Z45: =IFERROR((X45+Y45)/AR45,"") -> 0.797942 | AA45: 97120 | AB45: =IFERROR(AA45/F45,"") -> 0.41025641 | AC45: =IFERROR(AA45*1000/H45,"") -> 6115.869 | AD45: =IF(AB45="","",RANK(AB45,$AB$3:$AB$168,0)+COUNTIF($AB$3:AB45,AB45)-1) -> 116 | AE45: =IF(AA45="","",RANK(AA45,$AA$3:$AA$168,0)+COUNTIF($AA$3:AA45,AA45)-1) -> 36 | AF45: 91.86 | AG45: 1.0229429e+08 | AH45: =IFERROR(AG45/AZ45,"") -> 6568.6951 | AI45: 15412 | AJ45: =IFERROR(AI45/F45,"") -> 0.065103705 | AK45: 378 | AL45: 440 | AM45: 459 | AN45: 2003 | AO45: 1493 | AP45: 1.8 | AQ45: =IFERROR(AL45*1000/AZ45,"") -> 28.254029 | AR45: 1069 | AS45: 483 | AT45: 346 | AU45: 41 | AV45: 199 | AW45: =IFERROR(AS45/AR45,"") -> 0.45182413 | AX45: 8 | AY45: 8 | AZ45: 15573 | BA45: 176.302 | BB45: 88.33 | BC45: 0.585 | BD45: 54.9 | BE45: 99.36 | BF45: 5.3 | BG45: 4.4 | BH45: 22.75 | BI45: 2003 | BJ45: 1.8 | BK45: =IFERROR(BI45/AZ45,"") -> 0.12862005 | BL45: =IFERROR(AI45+K45+S45+AA45-F45,"") -> 0 | BM45: =IFERROR(F45+G45-C45,"") -> 0 | BN45: =IF(I45="","",IFERROR(C45*1000/H45-I45,"")) -> -0.028287154
A46: 2412609 | B46: São Paulo do Potengi | C46: 231552 | D46: 273442 | E46: 290640 | F46: 212966 | G46: 18586 | H46: 17858 | I46: 12966.29 | J46: 17314.45 | K46: 13377 | L46: =IFERROR(K46/F46,"") -> 0.062812843 | M46: =IFERROR(K46*1000/H46,"") -> 749.07604 | N46: =IF(L46="","",RANK(L46,$L$3:$L$168,0)+COUNTIF($L$3:L46,L46)-1) -> 77 | O46: =IF(K46="","",RANK(K46,$K$3:$K$168,0)+COUNTIF($K$3:K46,K46)-1) -> 61 | P46: 188 | Q46: =IFERROR(P46/AR46,"") -> 0.13642961 | R46: 11 | S46: 86723 | T46: =IFERROR(S46/F46,"") -> 0.40721524 | U46: =IFERROR(S46*1000/H46,"") -> 4856.2549 | V46: =IF(T46="","",RANK(T46,$T$3:$T$168,0)+COUNTIF($T$3:T46,T46)-1) -> 23 | W46: =IF(S46="","",RANK(S46,$S$3:$S$168,0)+COUNTIF($S$3:S46,S46)-1) -> 33 | X46: 499 | Y46: 679 | Z46: =IFERROR((X46+Y46)/AR46,"") -> 0.85486212 | AA46: 105894 | AB46: =IFERROR(AA46/F46,"") -> 0.4972343 | AC46: =IFERROR(AA46*1000/H46,"") -> 5929.7794 | AD46: =IF(AB46="","",RANK(AB46,$AB$3:$AB$168,0)+COUNTIF($AB$3:AB46,AB46)-1) -> 89 | AE46: =IF(AA46="","",RANK(AA46,$AA$3:$AA$168,0)+COUNTIF($AA$3:AA46,AA46)-1) -> 31 | AF46: 88.84 | AG46: 1.1490339e+08 | AH46: =IFERROR(AG46/AZ46,"") -> 6845.192 | AI46: 6972 | AJ46: =IFERROR(AI46/F46,"") -> 0.03273762 | AK46: 358 | AL46: 393 | AM46: 413 | AN46: 2007 | AO46: 1620 | AP46: 1.6 | AQ46: =IFERROR(AL46*1000/AZ46,"") -> 23.412367 | AR46: 1378 | AS46: 809 | AT46: 425 | AU46: 30 | AV46: 114 | AW46: =IFERROR(AS46/AR46,"") -> 0.58708273 | AX46: 5 | AY46: 7 | AZ46: 16786 | BA46: 240.425 | BB46: 69.82 | BC46: 0.622 | BD46: 47.7 | BE46: 100 | BF46: 4.7 | BG46: 3.7 | BH46: 55.12 | BI46: 2007 | BJ46: 1.6 | BK46: =IFERROR(BI46/AZ46,"") -> 0.11956392 | BL46: =IFERROR(AI46+K46+S46+AA46-F46,"") -> 0 | BM46: =IFERROR(F46+G46-C46,"") -> 0 | BN46: =IF(I46="","",IFERROR(C46*1000/H46-I46,"")) -> -0.00038190167
A47: 2414605 | B47: Upanema | C47: 214152 | D47: 330523 | E47: 370220 | F47: 201496 | G47: 12656 | H47: 14937 | I47: 14337.04 | J47: 27268.15 | K47: 40968 | L47: =IFERROR(K47/F47,"") -> 0.20331917 | M47: =IFERROR(K47*1000/H47,"") -> 2742.7194 | N47: =IF(L47="","",RANK(L47,$L$3:$L$168,0)+COUNTIF($L$3:L47,L47)-1) -> 34 | O47: =IF(K47="","",RANK(K47,$K$3:$K$168,0)+COUNTIF($K$3:K47,K47)-1) -> 41 | P47: 110 | Q47: =IFERROR(P47/AR47,"") -> 0.15942029 | R47: 14 | S47: 55723 | T47: =IFERROR(S47/F47,"") -> 0.27654643 | U47: =IFERROR(S47*1000/H47,"") -> 3730.5349 | V47: =IF(T47="","",RANK(T47,$T$3:$T$168,0)+COUNTIF($T$3:T47,T47)-1) -> 69 | W47: =IF(S47="","",RANK(S47,$S$3:$S$168,0)+COUNTIF($S$3:S47,S47)-1) -> 48 | X47: 273 | Y47: 285 | Z47: =IFERROR((X47+Y47)/AR47,"") -> 0.80869565 | AA47: 91275 | AB47: =IFERROR(AA47/F47,"") -> 0.45298666 | AC47: =IFERROR(AA47*1000/H47,"") -> 6110.6648 | AD47: =IF(AB47="","",RANK(AB47,$AB$3:$AB$168,0)+COUNTIF($AB$3:AB47,AB47)-1) -> 104 | AE47: =IF(AA47="","",RANK(AA47,$AA$3:$AA$168,0)+COUNTIF($AA$3:AA47,AA47)-1) -> 39 | AF47: 89.91 | AG47: 91993353 | AH47: =IFERROR(AG47/AZ47,"") -> 6775.676 | AI47: 13530 | AJ47: =IFERROR(AI47/F47,"") -> 0.067147735 | AK47: 263 | AL47: 284 | AM47: 290 | AN47: 1647 | AO47: 1356 | AP47: 2 | AQ47: =IFERROR(AL47*1000/AZ47,"") -> 20.917729 | AR47: 690 | AS47: 335 | AT47: 214 | AU47: 41 | AV47: 100 | AW47: =IFERROR(AS47/AR47,"") -> 0.48550725 | AX47: 13 | AY47: 9 | AZ47: 13577 | BA47: 873.14 | BB47: 15.55 | BC47: 0.596 | BD47: 55.4 | BE47: 99.53 | BF47: 5.2 | BG47: 4.8 | BH47: 17.48 | BI47: 1647 | BJ47: 2 | BK47: =IFERROR(BI47/AZ47,"") -> 0.12130809 | BL47: =IFERROR(AI47+K47+S47+AA47-F47,"") -> 0 | BM47: =IFERROR(F47+G47-C47,"") -> 0 | BN47: =IF(I47="","",IFERROR(C47*1000/H47-I47,"")) -> -0.024535047
A48: 2405603 | B48: Jardim de Piranhas | C48: 213313 | D48: 243966 | E48: 276161 | F48: 196355 | G48: 16959 | H48: 15044 | I48: 14179.29 | J48: 19758.23 | K48: 21275 | L48: =IFERROR(K48/F48,"") -> 0.10834967 | M48: =IFERROR(K48*1000/H48,"") -> 1414.1851 | N48: =IF(L48="","",RANK(L48,$L$3:$L$168,0)+COUNTIF($L$3:L48,L48)-1) -> 56 | O48: =IF(K48="","",RANK(K48,$K$3:$K$168,0)+COUNTIF($K$3:K48,K48)-1) -> 55 | P48: 193 | Q48: =IFERROR(P48/AR48,"") -> 0.24871134 | R48: 18 | S48: 65103 | T48: =IFERROR(S48/F48,"") -> 0.33155764 | U48: =IFERROR(S48*1000/H48,"") -> 4327.506 | V48: =IF(T48="","",RANK(T48,$T$3:$T$168,0)+COUNTIF($T$3:T48,T48)-1) -> 42 | W48: =IF(S48="","",RANK(S48,$S$3:$S$168,0)+COUNTIF($S$3:S48,S48)-1) -> 40 | X48: 341 | Y48: 232 | Z48: =IFERROR((X48+Y48)/AR48,"") -> 0.73840206 | AA48: 89061 | AB48: =IFERROR(AA48/F48,"") -> 0.45357134 | AC48: =IFERROR(AA48*1000/H48,"") -> 5920.0346 | AD48: =IF(AB48="","",RANK(AB48,$AB$3:$AB$168,0)+COUNTIF($AB$3:AB48,AB48)-1) -> 103 | AE48: =IF(AA48="","",RANK(AA48,$AA$3:$AA$168,0)+COUNTIF($AA$3:AA48,AA48)-1) -> 40 | AF48: 91.65 | AG48: 88953554 | AH48: =IFERROR(AG48/AZ48,"") -> 6364.2809 | AI48: 20915 | AJ48: =IFERROR(AI48/F48,"") -> 0.10651626 | AK48: 308 | AL48: 333 | AM48: 351 | AN48: 1853 | AO48: 1529 | AP48: 1.8 | AQ48: =IFERROR(AL48*1000/AZ48,"") -> 23.824855 | AR48: 776 | AS48: 332 | AT48: 327 | AU48: 30 | AV48: 87 | AW48: =IFERROR(AS48/AR48,"") -> 0.42783505 | AX48: 2 | AY48: 8 | AZ48: 13977 | BA48: 330.53 | BB48: 42.29 | BC48: 0.603 | BD48: 44.6 | BE48: 98.75 | BF48: 5.1 | BG48: 4.9 | BH48: 25.96 | BI48: 1853 | BJ48: 1.8 | BK48: =IFERROR(BI48/AZ48,"") -> 0.13257494 | BL48: =IFERROR(AI48+K48+S48+AA48-F48,"") -> -1 | BM48: =IFERROR(F48+G48-C48,"") -> 1 | BN48: =IF(I48="","",IFERROR(C48*1000/H48-I48,"")) -> -0.015870779
A49: 2402501 | B49: Carnaubais | C49: 210948 | D49: 302478 | E49: 231816 | F49: 203394 | G49: 7554 | H49: 10972 | I49: 19226.04 | J49: 23864.16 | K49: 74994 | L49: =IFERROR(K49/F49,"") -> 0.36871294 | M49: =IFERROR(K49*1000/H49,"") -> 6835.0346 | N49: =IF(L49="","",RANK(L49,$L$3:$L$168,0)+COUNTIF($L$3:L49,L49)-1) -> 20 | O49: =IF(K49="","",RANK(K49,$K$3:$K$168,0)+COUNTIF($K$3:K49,K49)-1) -> 36 | P49: 64 | Q49: =IFERROR(P49/AR49,"") -> 0.11700183 | R49: 11 | S49: 47258 | T49: =IFERROR(S49/F49,"") -> 0.23234707 | U49: =IFERROR(S49*1000/H49,"") -> 4307.1455 | V49: =IF(T49="","",RANK(T49,$T$3:$T$168,0)+COUNTIF($T$3:T49,T49)-1) -> 109 | W49: =IF(S49="","",RANK(S49,$S$3:$S$168,0)+COUNTIF($S$3:S49,S49)-1) -> 50 | X49: 194 | Y49: 255 | Z49: =IFERROR((X49+Y49)/AR49,"") -> 0.82084095 | AA49: 69035 | AB49: =IFERROR(AA49/F49,"") -> 0.33941513 | AC49: =IFERROR(AA49*1000/H49,"") -> 6291.9249 | AD49: =IF(AB49="","",RANK(AB49,$AB$3:$AB$168,0)+COUNTIF($AB$3:AB49,AB49)-1) -> 133 | AE49: =IF(AA49="","",RANK(AA49,$AA$3:$AA$168,0)+COUNTIF($AA$3:AA49,AA49)-1) -> 63 | AF49: 94.29 | AG49: 81673307 | AH49: =IFERROR(AG49/AZ49,"") -> 8407.7936 | AI49: 12107 | AJ49: =IFERROR(AI49/F49,"") -> 0.059524863 | AK49: 218 | AL49: 241 | AM49: 252 | AN49: 1028 | AO49: 827 | AP49: 1.9 | AQ49: =IFERROR(AL49*1000/AZ49,"") -> 24.809553 | AR49: 547 | AS49: 245 | AT49: 171 | AU49: 32 | AV49: 99 | AW49: =IFERROR(AS49/AR49,"") -> 0.44789762 | AX49: 25 | AY49: 9 | AZ49: 9714 | BA49: 517.737 | BB49: 18.76 | BC49: 0.589 | BD49: 50.7 | BE49: 99.36 | BF49: 5.4 | BG49: 5 | BH49: 26.52 | BI49: 1028 | BJ49: 1.9 | BK49: =IFERROR(BI49/AZ49,"") -> 0.10582664 | BL49: =IFERROR(AI49+K49+S49+AA49-F49,"") -> 0 | BM49: =IFERROR(F49+G49-C49,"") -> 0 | BN49: =IF(I49="","",IFERROR(C49*1000/H49-I49,"")) -> -0.010105724
A50: 2405702 | B50: Jardim do Seridó | C50: 207991 | D50: 237956 | E50: 244663 | F50: 187190 | G50: 20801 | H50: 12397 | I50: 16777.53 | J50: 20992.11 | K50: 30304 | L50: =IFERROR(K50/F50,"") -> 0.16188899 | M50: =IFERROR(K50*1000/H50,"") -> 2444.4624 | N50: =IF(L50="","",RANK(L50,$L$3:$L$168,0)+COUNTIF($L$3:L50,L50)-1) -> 43 | O50: =IF(K50="","",RANK(K50,$K$3:$K$168,0)+COUNTIF($K$3:K50,K50)-1) -> 47 | P50: 218 | Q50: =IFERROR(P50/AR50,"") -> 0.19516562 | R50: 21 | S50: 68528 | T50: =IFERROR(S50/F50,"") -> 0.36608793 | U50: =IFERROR(S50*1000/H50,"") -> 5527.789 | V50: =IF(T50="","",RANK(T50,$T$3:$T$168,0)+COUNTIF($T$3:T50,T50)-1) -> 32 | W50: =IF(S50="","",RANK(S50,$S$3:$S$168,0)+COUNTIF($S$3:S50,S50)-1) -> 39 | X50: 420 | Y50: 466 | Z50: =IFERROR((X50+Y50)/AR50,"") -> 0.79319606 | AA50: 71059 | AB50: =IFERROR(AA50/F50,"") -> 0.37960895 | AC50: =IFERROR(AA50*1000/H50,"") -> 5731.9513 | AD50: =IF(AB50="","",RANK(AB50,$AB$3:$AB$168,0)+COUNTIF($AB$3:AB50,AB50)-1) -> 121 | AE50: =IF(AA50="","",RANK(AA50,$AA$3:$AA$168,0)+COUNTIF($AA$3:AA50,AA50)-1) -> 59 | AF50: 83.65 | AG50: 71432891 | AH50: =IFERROR(AG50/AZ50,"") -> 6128.9482 | AI50: 17299 | AJ50: =IFERROR(AI50/F50,"") -> 0.092414125 | AK50: 393 | AL50: 433 | AM50: 462 | AN50: 2048 | AO50: 1586 | AP50: 1.6 | AQ50: =IFERROR(AL50*1000/AZ50,"") -> 37.151437 | AR50: 1117 | AS50: 593 | AT50: 364 | AU50: 51 | AV50: 109 | AW50: =IFERROR(AS50/AR50,"") -> 0.5308863 | AX50: 3 | AY50: 10 | AZ50: 11655 | BA50: 367.645 | BB50: 31.7 | BC50: 0.663 | BD50: 41.3 | BE50: 100 | BF50: 6.3 | BG50: 5.4 | BH50: 71.88 | BI50: 2048 | BJ50: 1.6 | BK50: =IFERROR(BI50/AZ50,"") -> 0.17571858 | BL50: =IFERROR(AI50+K50+S50+AA50-F50,"") -> 0 | BM50: =IFERROR(F50+G50-C50,"") -> 0 | BN50: =IF(I50="","",IFERROR(C50*1000/H50-I50,"")) -> -0.0031789949
A51: 2414001 | B51: Tangará | C51: 201782 | D51: 213678 | E51: 225000 | F51: 182311 | G51: 19471 | H51: 16008 | I51: 12605.08 | J51: 16941.5 | K51: 18673 | L51: =IFERROR(K51/F51,"") -> 0.10242388 | M51: =IFERROR(K51*1000/H51,"") -> 1166.4793 | N51: =IF(L51="","",RANK(L51,$L$3:$L$168,0)+COUNTIF($L$3:L51,L51)-1) -> 57 | O51: =IF(K51="","",RANK(K51,$K$3:$K$168,0)+COUNTIF($K$3:K51,K51)-1) -> 57 | P51: 96 | Q51: =IFERROR(P51/AR51,"") -> 0.10946408 | R51: 14 | S51: 64277 | T51: =IFERROR(S51/F51,"") -> 0.35256786 | U51: =IFERROR(S51*1000/H51,"") -> 4015.3048 | V51: =IF(T51="","",RANK(T51,$T$3:$T$168,0)+COUNTIF($T$3:T51,T51)-1) -> 36 | W51: =IF(S51="","",RANK(S51,$S$3:$S$168,0)+COUNTIF($S$3:S51,S51)-1) -> 44 | X51: 400 | Y51: 368 | Z51: =IFERROR((X51+Y51)/AR51,"") -> 0.87571266 | AA51: 94105 | AB51: =IFERROR(AA51/F51,"") -> 0.5161784 | AC51: =IFERROR(AA51*1000/H51,"") -> 5878.6232 | AD51: =IF(AB51="","",RANK(AB51,$AB$3:$AB$168,0)+COUNTIF($AB$3:AB51,AB51)-1) -> 85 | AE51: =IF(AA51="","",RANK(AA51,$AA$3:$AA$168,0)+COUNTIF($AA$3:AA51,AA51)-1) -> 38 | AF51: 88.69 | AG51: 91171164 | AH51: =IFERROR(AG51/AZ51,"") -> 6864.7816 | AI51: 5256 | AJ51: =IFERROR(AI51/F51,"") -> 0.028829857 | AK51: 281 | AL51: 320 | AM51: 324 | AN51: 1449 | AO51: 1148 | AP51: 2.1 | AQ51: =IFERROR(AL51*1000/AZ51,"") -> 24.094571 | AR51: 877 | AS51: 477 | AT51: 274 | AU51: 35 | AV51: 91 | AW51: =IFERROR(AS51/AR51,"") -> 0.54389966 | AX51: 6 | AY51: 6 | AZ51: 13281 | BA51: 339.484 | BB51: 39.12 | BC51: 0.608 | BD51: 51.1 | BE51: 99.58 | BF51: 4.4 | BG51: 4.3 | BH51: 53.25 | BI51: 1449 | BJ51: 2.1 | BK51: =IFERROR(BI51/AZ51,"") -> 0.10910323 | BL51: =IFERROR(AI51+K51+S51+AA51-F51,"") -> 0 | BM51: =IFERROR(F51+G51-C51,"") -> 0 | BN51: =IF(I51="","",IFERROR(C51*1000/H51-I51,"")) -> -0.0075362319
A52: 2404705 | B52: Ipanguaçu | C52: 196498 | D52: 215667 | E52: 263825 | F52: 183123 | G52: 13375 | H52: 15759 | I52: 12468.96 | J52: 18669.94 | K52: 7935 | L52: =IFERROR(K52/F52,"") -> 0.043331531 | M52: =IFERROR(K52*1000/H52,"") -> 503.5218 | N52: =IF(L52="","",RANK(L52,$L$3:$L$168,0)+COUNTIF($L$3:L52,L52)-1) -> 107 | O52: =IF(K52="","",RANK(K52,$K$3:$K$168,0)+COUNTIF($K$3:K52,K52)-1) -> 73 | P52: 79 | Q52: =IFERROR(P52/AR52,"") -> 0.13210702 | R52: 7 | S52: 40826 | T52: =IFERROR(S52/F52,"") -> 0.22294305 | U52: =IFERROR(S52*1000/H52,"") -> 2590.6466 | V52: =IF(T52="","",RANK(T52,$T$3:$T$168,0)+COUNTIF($T$3:T52,T52)-1) -> 120 | W52: =IF(S52="","",RANK(S52,$S$3:$S$168,0)+COUNTIF($S$3:S52,S52)-1) -> 60 | X52: 216 | Y52: 272 | Z52: =IFERROR((X52+Y52)/AR52,"") -> 0.81605351 | AA52: 86022 | AB52: =IFERROR(AA52/F52,"") -> 0.46974984 | AC52: =IFERROR(AA52*1000/H52,"") -> 5458.5951 | AD52: =IF(AB52="","",RANK(AB52,$AB$3:$AB$168,0)+COUNTIF($AB$3:AB52,AB52)-1) -> 97 | AE52: =IF(AA52="","",RANK(AA52,$AA$3:$AA$168,0)+COUNTIF($AA$3:AA52,AA52)-1) -> 42 | AF52: 94.32 | AG52: 83407398 | AH52: =IFERROR(AG52/AZ52,"") -> 5902.4413 | AI52: 48341 | AJ52: =IFERROR(AI52/F52,"") -> 0.26398104 | AK52: 297 | AL52: 369 | AM52: 376 | AN52: 1904 | AO52: 1563 | AP52: 1.6 | AQ52: =IFERROR(AL52*1000/AZ52,"") -> 26.112802 | AR52: 598 | AS52: 223 | AT52: 222 | AU52: 22 | AV52: 131 | AW52: =IFERROR(AS52/AR52,"") -> 0.3729097 | AX52: 24 | AY52: 7 | AZ52: 14131 | BA52: 374.245 | BB52: 37.76 | BC52: 0.603 | BD52: 47.1 | BE52: 98.28 | BF52: 5.3 | BG52: 3.8 | BH52: 0.96 | BI52: 1904 | BJ52: 1.6 | BK52: =IFERROR(BI52/AZ52,"") -> 0.13473923 | BL52: =IFERROR(AI52+K52+S52+AA52-F52,"") -> 1 | BM52: =IFERROR(F52+G52-C52,"") -> 0 | BN52: =IF(I52="","",IFERROR(C52*1000/H52-I52,"")) -> -0.021615585
A53: 2410900 | B53: Riachuelo | C53: 192156 | D53: 345300 | E53: 319931 | F53: 180300 | G53: 11856 | H53: 8310 | I53: 23123.45 | J53: 43298.29 | K53: 84834 | L53: =IFERROR(K53/F53,"") -> 0.47051581 | M53: =IFERROR(K53*1000/H53,"") -> 10208.664 | N53: =IF(L53="","",RANK(L53,$L$3:$L$168,0)+COUNTIF($L$3:L53,L53)-1) -> 14 | O53: =IF(K53="","",RANK(K53,$K$3:$K$168,0)+COUNTIF($K$3:K53,K53)-1) -> 26 | P53: 43 | Q53: =IFERROR(P53/AR53,"") -> 0.13230769 | R53: 10 | S53: 39733 | T53: =IFERROR(S53/F53,"") -> 0.2203716 | U53: =IFERROR(S53*1000/H53,"") -> 4781.3478 | V53: =IF(T53="","",RANK(T53,$T$3:$T$168,0)+COUNTIF($T$3:T53,T53)-1) -> 124 | W53: =IF(S53="","",RANK(S53,$S$3:$S$168,0)+COUNTIF($S$3:S53,S53)-1) -> 64 | X53: 134 | Y53: 136 | Z53: =IFERROR((X53+Y53)/AR53,"") -> 0.83076923 | AA53: 53625 | AB53: =IFERROR(AA53/F53,"") -> 0.29742097 | AC53: =IFERROR(AA53*1000/H53,"") -> 6453.0686 | AD53: =IF(AB53="","",RANK(AB53,$AB$3:$AB$168,0)+COUNTIF($AB$3:AB53,AB53)-1) -> 137 | AE53: =IF(AA53="","",RANK(AA53,$AA$3:$AA$168,0)+COUNTIF($AA$3:AA53,AA53)-1) -> 80 | AF53: 81.42 | AG53: 82118223 | AH53: =IFERROR(AG53/AZ53,"") -> 11113.577 | AI53: 2108 | AJ53: =IFERROR(AI53/F53,"") -> 0.011691625 | AK53: 127 | AL53: 131 | AM53: 133 | AN53: 817 | AO53: 713 | AP53: 2 | AQ53: =IFERROR(AL53*1000/AZ53,"") -> 17.729057 | AR53: 325 | AS53: 149 | AT53: 109 | AU53: 4 | AV53: 63 | AW53: =IFERROR(AS53/AR53,"") -> 0.45846154 | AX53: 3 | AY53: 9 | AZ53: 7389 | BA53: 262.88 | BB53: 28.11 | BC53: 0.592 | BD53: 51.5 | BE53: 99.52 | BF53: 4.7 | BG53: 4.1 | BH53: 52.04 | BI53: 817 | BJ53: 2 | BK53: =IFERROR(BI53/AZ53,"") -> 0.11056977 | BL53: =IFERROR(AI53+K53+S53+AA53-F53,"") -> 0 | BM53: =IFERROR(F53+G53-C53,"") -> 0 | BN53: =IF(I53="","",IFERROR(C53*1000/H53-I53,"")) -> 0.015703971
A54: 2408953 | B54: Rio do Fogo | C54: 185590 | D54: 211825 | E54: 207249 | F54: 176112 | G54: 9478 | H54: 10961 | I54: 16931.82 | J54: 20022.14 | K54: 31176 | L54: =IFERROR(K54/F54,"") -> 0.17702371 | M54: =IFERROR(K54*1000/H54,"") -> 2844.266 | N54: =IF(L54="","",RANK(L54,$L$3:$L$168,0)+COUNTIF($L$3:L54,L54)-1) -> 39 | O54: =IF(K54="","",RANK(K54,$K$3:$K$168,0)+COUNTIF($K$3:K54,K54)-1) -> 46 | P54: 54 | Q54: =IFERROR(P54/AR54,"") -> 0.098540146 | R54: 8 | S54: 35592 | T54: =IFERROR(S54/F54,"") -> 0.20209866 | U54: =IFERROR(S54*1000/H54,"") -> 3247.149 | V54: =IF(T54="","",RANK(T54,$T$3:$T$168,0)+COUNTIF($T$3:T54,T54)-1) -> 140 | W54: =IF(S54="","",RANK(S54,$S$3:$S$168,0)+COUNTIF($S$3:S54,S54)-1) -> 66 | X54: 187 | Y54: 262 | Z54: =IFERROR((X54+Y54)/AR54,"") -> 0.81934307 | AA54: 76527 | AB54: =IFERROR(AA54/F54,"") -> 0.43453598 | AC54: =IFERROR(AA54*1000/H54,"") -> 6981.7535 | AD54: =IF(AB54="","",RANK(AB54,$AB$3:$AB$168,0)+COUNTIF($AB$3:AB54,AB54)-1) -> 111 | AE54: =IF(AA54="","",RANK(AA54,$AA$3:$AA$168,0)+COUNTIF($AA$3:AA54,AA54)-1) -> 49 | AF54: 89.28 | AG54: 86654246 | AH54: =IFERROR(AG54/AZ54,"") -> 8371.582 | AI54: 32817 | AJ54: =IFERROR(AI54/F54,"") -> 0.18634165 | AK54: 204 | AL54: 209 | AM54: 210 | AN54: 817 | AO54: 619 | AP54: 1.3 | AQ54: =IFERROR(AL54*1000/AZ54,"") -> 20.191286 | AR54: 548 | AS54: 259 | AT54: 188 | AU54: 7 | AV54: 94 | AW54: =IFERROR(AS54/AR54,"") -> 0.47262774 | AX54: 40 | AY54: 5 | AZ54: 10351 | BA54: 151.097 | BB54: 68.51 | BC54: 0.569 | BD54: 51.8 | BE54: 99.18 | BF54: 4.5 | BG54: 4.3 | BH54: 1.99 | BI54: 817 | BJ54: 1.9 | BK54: =IFERROR(BI54/AZ54,"") -> 0.078929572 | BL54: =IFERROR(AI54+K54+S54+AA54-F54,"") -> 0 | BM54: =IFERROR(F54+G54-C54,"") -> 0 | BN54: =IF(I54="","",IFERROR(C54*1000/H54-I54,"")) -> 0.029283824
A55: 2400802 | B55: Angicos | C55: 180163 | D55: 214393 | E55: 257919 | F55: 163136 | G55: 17027 | H55: 11695 | I55: 15405.14 | J55: 22173.27 | K55: 6847 | L55: =IFERROR(K55/F55,"") -> 0.041971116 | M55: =IFERROR(K55*1000/H55,"") -> 585.46387 | N55: =IF(L55="","",RANK(L55,$L$3:$L$168,0)+COUNTIF($L$3:L55,L55)-1) -> 113 | O55: =IF(K55="","",RANK(K55,$K$3:$K$168,0)+COUNTIF($K$3:K55,K55)-1) -> 79 | P55: 120 | Q55: =IFERROR(P55/AR55,"") -> 0.13172338 | R55: 13 | S55: 78364 | T55: =IFERROR(S55/F55,"") -> 0.48035995 | U55: =IFERROR(S55*1000/H55,"") -> 6700.6413 | V55: =IF(T55="","",RANK(T55,$T$3:$T$168,0)+COUNTIF($T$3:T55,T55)-1) -> 11 | W55: =IF(S55="","",RANK(S55,$S$3:$S$168,0)+COUNTIF($S$3:S55,S55)-1) -> 37 | X55: 347 | Y55: 426 | Z55: =IFERROR((X55+Y55)/AR55,"") -> 0.84851811 | AA55: 71611 | AB55: =IFERROR(AA55/F55,"") -> 0.43896504 | AC55: =IFERROR(AA55*1000/H55,"") -> 6123.215 | AD55: =IF(AB55="","",RANK(AB55,$AB$3:$AB$168,0)+COUNTIF($AB$3:AB55,AB55)-1) -> 109 | AE55: =IF(AA55="","",RANK(AA55,$AA$3:$AA$168,0)+COUNTIF($AA$3:AA55,AA55)-1) -> 58 | AF55: 92.34 | AG55: 64460124 | AH55: =IFERROR(AG55/AZ55,"") -> 5541.62 | AI55: 6314 | AJ55: =IFERROR(AI55/F55,"") -> 0.038703903 | AK55: 397 | AL55: 457 | AM55: 470 | AN55: 1394 | AO55: 926 | AP55: 1.6 | AQ55: =IFERROR(AL55*1000/AZ55,"") -> 39.288171 | AR55: 911 | AS55: 388 | AT55: 363 | AU55: 37 | AV55: 123 | AW55: =IFERROR(AS55/AR55,"") -> 0.4259056 | AX55: 10 | AY55: 8 | AZ55: 11632 | BA55: 741.582 | BB55: 15.69 | BC55: 0.624 | BD55: 49.2 | BE55: 98.65 | BF55: 4.9 | BG55: 4.8 | BH55: 13.33 | BI55: 1394 | BJ55: 1.6 | BK55: =IFERROR(BI55/AZ55,"") -> 0.11984182 | BL55: =IFERROR(AI55+K55+S55+AA55-F55,"") -> 0 | BM55: =IFERROR(F55+G55-C55,"") -> 0 | BN55: =IF(I55="","",IFERROR(C55*1000/H55-I55,"")) -> -0.0096023942
... A94: 2401305 | B94: Campo Grande | C94: 105354 | D94: 119802 | E94: 136391 | F94: 99870 | G94: 5484 | H94: 9686 | I94: 10876.94 | J94: 14017.6 | K94: 3784 | L94: =IFERROR(K94/F94,"") -> 0.037889256 | M94: =IFERROR(K94*1000/H94,"") -> 390.66694 | N94: =IF(L94="","",RANK(L94,$L$3:$L$168,0)+COUNTIF($L$3:L94,L94)-1) -> 134 | O94: =IF(K94="","",RANK(K94,$K$3:$K$168,0)+COUNTIF($K$3:K94,K94)-1) -> 106 | P94: 49 | Q94: =IFERROR(P94/AR94,"") -> 0.1147541 | R94: 16 | S94: 30123 | T94: =IFERROR(S94/F94,"") -> 0.30162211 | U94: =IFERROR(S94*1000/H94,"") -> 3109.9525 | V94: =IF(T94="","",RANK(T94,$T$3:$T$168,0)+COUNTIF($T$3:T94,T94)-1) -> 54 | W94: =IF(S94="","",RANK(S94,$S$3:$S$168,0)+COUNTIF($S$3:S94,S94)-1) -> 76 | X94: 143 | Y94: 217 | Z94: =IFERROR((X94+Y94)/AR94,"") -> 0.84309133 | AA94: 55108 | AB94: =IFERROR(AA94/F94,"") -> 0.55179734 | AC94: =IFERROR(AA94*1000/H94,"") -> 5689.4487 | AD94: =IF(AB94="","",RANK(AB94,$AB$3:$AB$168,0)+COUNTIF($AB$3:AB94,AB94)-1) -> 74 | AE94: =IF(AA94="","",RANK(AA94,$AA$3:$AA$168,0)+COUNTIF($AA$3:AA94,AA94)-1) -> 79 | AF94: 94.32 | AG94: 51546757 | AH94: =IFERROR(AG94/AZ94,"") -> 5297.714 | AI94: 10856 | AJ94: =IFERROR(AI94/F94,"") -> 0.10870131 | AK94: 221 | AL94: 231 | AM94: 242 | AN94: 619 | AO94: 404 | AP94: 1.9 | AQ94: =IFERROR(AL94*1000/AZ94,"") -> 23.741007 | AR94: 427 | AS94: 130 | AT94: 121 | AU94: 61 | AV94: 115 | AW94: =IFERROR(AS94/AR94,"") -> 0.30444965 | AX94: 11 | AY94: 7 | AZ94: 9730 | BA94: 890.89 | BB94: 10.92 | BC94: 0.621 | BD94: 51.7 | BE94: 98.18 | BF94: 5 | BG94: 4.5 | BH94: 3 | BI94: 614 | BJ94: 1.9 | BK94: =IFERROR(BI94/AZ94,"") -> 0.063103803 | BL94: =IFERROR(AI94+K94+S94+AA94-F94,"") -> 1 | BM94: =IFERROR(F94+G94-C94,"") -> 0 | BN94: =IF(I94="","",IFERROR(C94*1000/H94-I94,"")) -> -0.0042163948
A95: 2405108 | B95: Jandaíra | C95: 101429 | D95: 234017 | E95: 363648 | F95: 82665 | G95: 18764 | H95: 6907 | I95: 14684.92 | J95: 55417.28 | K95: 3878 | L95: =IFERROR(K95/F95,"") -> 0.046912236 | M95: =IFERROR(K95*1000/H95,"") -> 561.45939 | N95: =IF(L95="","",RANK(L95,$L$3:$L$168,0)+COUNTIF($L$3:L95,L95)-1) -> 93 | O95: =IF(K95="","",RANK(K95,$K$3:$K$168,0)+COUNTIF($K$3:K95,K95)-1) -> 103 | P95: 56 | Q95: =IFERROR(P95/AR95,"") -> 0.15598886 | R95: 27 | S95: 22218 | T95: =IFERROR(S95/F95,"") -> 0.26877155 | U95: =IFERROR(S95*1000/H95,"") -> 3216.7366 | V95: =IF(T95="","",RANK(T95,$T$3:$T$168,0)+COUNTIF($T$3:T95,T95)-1) -> 77 | W95: =IF(S95="","",RANK(S95,$S$3:$S$168,0)+COUNTIF($S$3:S95,S95)-1) -> 93 | X95: 129 | Y95: 152 | Z95: =IFERROR((X95+Y95)/AR95,"") -> 0.78272981 | AA95: 48265 | AB95: =IFERROR(AA95/F95,"") -> 0.58386258 | AC95: =IFERROR(AA95*1000/H95,"") -> 6987.8384 | AD95: =IF(AB95="","",RANK(AB95,$AB$3:$AB$168,0)+COUNTIF($AB$3:AB95,AB95)-1) -> 62 | AE95: =IF(AA95="","",RANK(AA95,$AA$3:$AA$168,0)+COUNTIF($AA$3:AA95,AA95)-1) -> 85 | AF95: 87.79 | AG95: 68276051 | AH95: =IFERROR(AG95/AZ95,"") -> 10404.762 | AI95: 8303 | AJ95: =IFERROR(AI95/F95,"") -> 0.10044154 | AK95: 146 | AL95: 154 | AM95: 155 | AN95: 1110 | AO95: 993 | AP95: 1.7 | AQ95: =IFERROR(AL95*1000/AZ95,"") -> 23.468455 | AR95: 359 | AS95: 155 | AT95: 95 | AU95: 20 | AV95: 89 | AW95: =IFERROR(AS95/AR95,"") -> 0.43175487 | AX95: 16 | AY95: 6 | AZ95: 6562 | BA95: 442.754 | BB95: 14.82 | BC95: 0.569 | BD95: 50.4 | BE95: 98.12 | BF95: 4.8 | BH95: 1.36 | BI95: 1110 | BJ95: 1.7 | BK95: =IFERROR(BI95/AZ95,"") -> 0.16915575 | BL95: =IFERROR(AI95+K95+S95+AA95-F95,"") -> -1 | BM95: =IFERROR(F95+G95-C95,"") -> 0 | BN95: =IF(I95="","",IFERROR(C95*1000/H95-I95,"")) -> 0.037289706
A96: 2404853 | B96: Itajá | C96: 99444 | D96: 145395 | E96: 179988 | F96: 90584 | G96: 8859 | H96: 7641 | I96: 13014.47 | J96: 24682.92 | K96: 10198 | L96: =IFERROR(K96/F96,"") -> 0.11258059 | M96: =IFERROR(K96*1000/H96,"") -> 1334.6421 | N96: =IF(L96="","",RANK(L96,$L$3:$L$168,0)+COUNTIF($L$3:L96,L96)-1) -> 54 | O96: =IF(K96="","",RANK(K96,$K$3:$K$168,0)+COUNTIF($K$3:K96,K96)-1) -> 67 | P96: 83 | Q96: =IFERROR(P96/AR96,"") -> 0.17043121 | R96: 13 | S96: 32214 | T96: =IFERROR(S96/F96,"") -> 0.35562572 | U96: =IFERROR(S96*1000/H96,"") -> 4215.9403 | V96: =IF(T96="","",RANK(T96,$T$3:$T$168,0)+COUNTIF($T$3:T96,T96)-1) -> 33 | W96: =IF(S96="","",RANK(S96,$S$3:$S$168,0)+COUNTIF($S$3:S96,S96)-1) -> 71 | X96: 173 | Y96: 225 | Z96: =IFERROR((X96+Y96)/AR96,"") -> 0.81724846 | AA96: 44885 | AB96: =IFERROR(AA96/F96,"") -> 0.49550693 | AC96: =IFERROR(AA96*1000/H96,"") -> 5874.2311 | AD96: =IF(AB96="","",RANK(AB96,$AB$3:$AB$168,0)+COUNTIF($AB$3:AB96,AB96)-1) -> 90 | AE96: =IF(AA96="","",RANK(AA96,$AA$3:$AA$168,0)+COUNTIF($AA$3:AA96,AA96)-1) -> 93 | AF96: 94.4 | AG96: 59622706 | AH96: =IFERROR(AG96/AZ96,"") -> 8176.4544 | AI96: 3287 | AJ96: =IFERROR(AI96/F96,"") -> 0.036286761 | AK96: 200 | AL96: 233 | AM96: 237 | AN96: 1487 | AO96: 1244 | AP96: 1.4 | AQ96: =IFERROR(AL96*1000/AZ96,"") -> 31.952825 | AR96: 487 | AS96: 204 | AT96: 190 | AU96: 24 | AV96: 69 | AW96: =IFERROR(AS96/AR96,"") -> 0.41889117 | AX96: 0 | AY96: 6 | AZ96: 7292 | BA96: 203.624 | BB96: 35.81 | BC96: 0.624 | BD96: 44.1 | BE96: 99.01 | BF96: 5.3 | BG96: 3.9 | BH96: 4.24 | BI96: 1487 | BJ96: 1.4 | BK96: =IFERROR(BI96/AZ96,"") -> 0.20392211 | BL96: =IFERROR(AI96+K96+S96+AA96-F96,"") -> 0 | BM96: =IFERROR(F96+G96-C96,"") -> -1 | BN96: =IF(I96="","",IFERROR(C96*1000/H96-I96,"")) -> 0.056894386
A97: 2403509 | B97: Espírito Santo | C97: 97584 | D97: 113844 | E97: 126682 | F97: 91985 | G97: 5599 | H97: 10463 | I97: 9326.6 | J97: 11928.61 | K97: 3117 | L97: =IFERROR(K97/F97,"") -> 0.03388596 | M97: =IFERROR(K97*1000/H97,"") -> 297.90691 | N97: =IF(L97="","",RANK(L97,$L$3:$L$168,0)+COUNTIF($L$3:L97,L97)-1) -> 142 | O97: =IF(K97="","",RANK(K97,$K$3:$K$168,0)+COUNTIF($K$3:K97,K97)-1) -> 114 | P97: 34 | Q97: =IFERROR(P97/AR97,"") -> 0.062385321 | R97: 4 | S97: 22482 | T97: =IFERROR(S97/F97,"") -> 0.24440941 | U97: =IFERROR(S97*1000/H97,"") -> 2148.7145 | V97: =IF(T97="","",RANK(T97,$T$3:$T$168,0)+COUNTIF($T$3:T97,T97)-1) -> 98 | W97: =IF(S97="","",RANK(S97,$S$3:$S$168,0)+COUNTIF($S$3:S97,S97)-1) -> 92 | X97: 114 | Y97: 386 | Z97: =IFERROR((X97+Y97)/AR97,"") -> 0.91743119 | AA97: 61582 | AB97: =IFERROR(AA97/F97,"") -> 0.66947872 | AC97: =IFERROR(AA97*1000/H97,"") -> 5885.6924 | AD97: =IF(AB97="","",RANK(AB97,$AB$3:$AB$168,0)+COUNTIF($AB$3:AB97,AB97)-1) -> 22 | AE97: =IF(AA97="","",RANK(AA97,$AA$3:$AA$168,0)+COUNTIF($AA$3:AA97,AA97)-1) -> 72 | AF97: 90.5 | AG97: 64955524 | AH97: =IFERROR(AG97/AZ97,"") -> 6116.3393 | AI97: 4803 | AJ97: =IFERROR(AI97/F97,"") -> 0.052215035 | AK97: 193 | AL97: 275 | AM97: 281 | AN97: 2038 | AO97: 1794 | AP97: 1.3 | AQ97: =IFERROR(AL97*1000/AZ97,"") -> 25.894539 | AR97: 545 | AS97: 176 | AT97: 79 | AU97: 6 | AV97: 284 | AW97: =IFERROR(AS97/AR97,"") -> 0.32293578 | AX97: 5 | AY97: 6 | AZ97: 10620 | BA97: 135.837 | BB97: 78.18 | BC97: 0.558 | BD97: 52.4 | BE97: 98.23 | BF97: 4.3 | BG97: 4.1 | BH97: 15.69 | BI97: 2036 | BJ97: 1.3 | BK97: =IFERROR(BI97/AZ97,"") -> 0.19171375 | BL97: =IFERROR(AI97+K97+S97+AA97-F97,"") -> -1 | BM97: =IFERROR(F97+G97-C97,"") -> 0 | BN97: =IF(I97="","",IFERROR(C97*1000/H97-I97,"")) -> -0.02062506
A98: 2406601 | B98: Lagoa Salgada | C98: 94311 | D98: 113114 | E98: 124483 | F98: 89408 | G98: 4902 | H98: 8348 | I98: 11297.4 | J98: 14963.74 | K98: 3545 | L98: =IFERROR(K98/F98,"") -> 0.039649696 | M98: =IFERROR(K98*1000/H98,"") -> 424.65261 | N98: =IF(L98="","",RANK(L98,$L$3:$L$168,0)+COUNTIF($L$3:L98,L98)-1) -> 125 | O98: =IF(K98="","",RANK(K98,$K$3:$K$168,0)+COUNTIF($K$3:K98,K98)-1) -> 110 | P98: 72 | Q98: =IFERROR(P98/AR98,"") -> 0.140625 | R98: 4 | S98: 26199 | T98: =IFERROR(S98/F98,"") -> 0.29302747 | U98: =IFERROR(S98*1000/H98,"") -> 3138.3565 | V98: =IF(T98="","",RANK(T98,$T$3:$T$168,0)+COUNTIF($T$3:T98,T98)-1) -> 58 | W98: =IF(S98="","",RANK(S98,$S$3:$S$168,0)+COUNTIF($S$3:S98,S98)-1) -> 83 | X98: 238 | Y98: 191 | Z98: =IFERROR((X98+Y98)/AR98,"") -> 0.83789062 | AA98: 55367 | AB98: =IFERROR(AA98/F98,"") -> 0.61926226 | AC98: =IFERROR(AA98*1000/H98,"") -> 6632.367 | AD98: =IF(AB98="","",RANK(AB98,$AB$3:$AB$168,0)+COUNTIF($AB$3:AB98,AB98)-1) -> 44 | AE98: =IF(AA98="","",RANK(AA98,$AA$3:$AA$168,0)+COUNTIF($AA$3:AA98,AA98)-1) -> 78 | AF98: 93.8 | AG98: 49841699 | AH98: =IFERROR(AG98/AZ98,"") -> 5991.3089 | AI98: 4297 | AJ98: =IFERROR(AI98/F98,"") -> 0.048060576 | AK98: 144 | AL98: 162 | AM98: 166 | AN98: 896 | AO98: 768 | AP98: 1.4 | AQ98: =IFERROR(AL98*1000/AZ98,"") -> 19.473494 | AR98: 512 | AS98: 278 | AT98: 167 | AU98: 12 | AV98: 55 | AW98: =IFERROR(AS98/AR98,"") -> 0.54296875 | AX98: 5 | AY98: 6 | AZ98: 8319 | BA98: 79.128 | BB98: 105.13 | BC98: 0.582 | BD98: 52.2 | BE98: 100 | BF98: 4.8 | BG98: 4.1 | BH98: 0.48 | BI98: 896 | BJ98: 1.4 | BK98: =IFERROR(BI98/AZ98,"") -> 0.10770525 | BL98: =IFERROR(AI98+K98+S98+AA98-F98,"") -> 0 | BM98: =IFERROR(F98+G98-C98,"") -> -1 | BN98: =IF(I98="","",IFERROR(C98*1000/H98-I98,"")) -> 0.036511739
